Workbook

Sheet START HERE
A1: Welcome to the new and improved 2026 time tracker, complete with better separation of pay periods and tracking of leave types such as PTO, Bank Time, the Floating Holiday, and Training Time.
A2: To use this template, go to File > Make a Copy > Save to Drive
A3: In your personal copy, change the values in the red outlined cells below (Earning Rate, PTO, Bank). The values for F.Holiday and Training are pre-populated.
A4: If you run into formula errors, or have questions on how to use, please reach out!
A6: Earning Rate | B6: 5
A8: End of 2025 Totals | D8: Start of 2026 Totals
A9: PTO | B9: 71.5 | D9: F.Holiday | E9: 8
A10: Bank | B10: 0 | D10: Training | E10: 40
A13: Tips:
A14: In the Bank-Save and Bank-Use columns for each pay period, enter the value you earned for compensation time in the Bank-Save column and enter the value for used compensation time in the Bank-Use column.
A15: Remember you cannot save and use compensation time in the same pay period.
A16: Holiday times have been pre-populated in each pay period according to the Federal Holiday Schedule for 2026.

Sheet Apr 26
A1: April | B1: PTO Totals | C1: Bank Totals | D1: F.Holiday Total | E1: Training Total
A2: Start of Month | B2: {=INDIRECT(TEXT(EDATE(DATE(2026, MATCH($A$1, {"January","February","March","April","May","June","July","August","September","October","November","December"}, 0), 1), -1), "mmm") & " 26!B4")} -> 51.5 | C2: {=INDIRECT(TEXT(EDATE(DATE(2026, MATCH($A$1, {"January","February","March","April","May","June","July","August","September","October","November","December"}, 0), 1), -1), "mmm") & " 26!C4")} -> 0 | D2: {=INDIRECT(TEXT(EDATE(DATE(2026, MATCH($A$1, {"January","February","March","April","May","June","July","August","September","October","November","December"}, 0), 1), -1), "mmm") & " 26!D4")} -> 8 | E2: {=INDIRECT(TEXT(EDATE(DATE(2026, MATCH($A$1, {"January","February","March","April","May","June","July","August","September","October","November","December"}, 0), 1), -1), "mmm") & " 26!E4")} -> 40 | G2: Earning Rate | H2: ='START HERE'!B6 -> 5
A3: End of Period 1 | B3: =B2+H2-F22 -> 56.5 | C3: =C2+D22-E22 -> 1 | D3: =D2-I22 -> 8 | E3: =E2-J22 -> 40
A4: End of Period 2 | B4: =B3+H2-F42 -> 61.5 | C4: =C3+D42-E42 -> 2.25 | D4: =D3-I42 -> 8 | E4: =E3-J42 -> 40
P5: IN | Q5: OUT | R5: Duration
A6: Pay Period 1 | B6: Weekday | C6: {=TRANSPOSE('Time Types'!A2:A11)} -> Regular | D6: Bank-Save | E6: Bank-Use | F6: PTO | G6: Holiday | H6: Government | I6: F.Holiday | J6: Training | K6: Overhead | L6: Other | M6: Total | N6: Estimated
A7: =DATE(2026, MONTH(DATEVALUE($A$1 & " 1")), 1) -> 46113 | B7: =text(A7,"ddd") -> Wed | C7: 6.75 | G7: =IF(COUNTIF(Holidays!$A$2:$A$12,$A7)>0, 8,"") | M7: =sum(C7:L7) -> 6.75 | N7: =IF(OR(B7="Sat", B7="Sun"), "", 8) -> 8 | P7: 0.42708333 | Q7: 0.70833333 | R7: =(Q7-P7)*24 -> 6.75
A8: =A7+1 -> 46114 | B8: =text(A8,"ddd") -> Thu | C8: 8.75 | G8: =IF(COUNTIF(Holidays!$A$2:$A$12,$A8)>0, 8,"") | M8: =sum(C8:L8) -> 8.75 | N8: =IF(OR(B8="Sat", B8="Sun"), "", 8) -> 8 | P8: 0.34375 | Q8: 0.70833333 | R8: =(Q8-P8)*24 -> 8.75
A9: =A8+1 -> 46115 | B9: =text(A9,"ddd") -> Fri | C9: 8 | G9: =IF(COUNTIF(Holidays!$A$2:$A$12,$A9)>0, 8,"") | M9: =sum(C9:L9) -> 8 | N9: =IF(OR(B9="Sat", B9="Sun"), "", 8) -> 8 | P9: 0.38541667 | Q9: 0.71875 | R9: =(Q9-P9)*24 -> 8
A10: =A9+1 -> 46116 | B10: =text(A10,"ddd") -> Sat | G10: =IF(COUNTIF(Holidays!$A$2:$A$12,$A10)>0, 8,"") | N10: =IF(OR(B10="Sat", B10="Sun"), "", 8) | P10: - | Q10: - | R10: -
A11: =A10+1 -> 46117 | B11: =text(A11,"ddd") -> Sun | G11: =IF(COUNTIF(Holidays!$A$2:$A$12,$A11)>0, 8,"") | N11: =IF(OR(B11="Sat", B11="Sun"), "", 8) | P11: - | Q11: - | R11: -
A12: =A11+1 -> 46118 | B12: =text(A12,"ddd") -> Mon | C12: 7.5 | G12: =IF(COUNTIF(Holidays!$A$2:$A$12,$A12)>0, 8,"") | M12: =sum(C12:L12) -> 7.5 | N12: =IF(OR(B12="Sat", B12="Sun"), "", 8) -> 8 | P12: 0.36805556 | Q12: 0.72222222 | R12: =(Q12-P12)*24-1 -> 7.5
A13: =A12+1 -> 46119 | B13: =text(A13,"ddd") -> Tue | C13: 6.25 | G13: =IF(COUNTIF(Holidays!$A$2:$A$12,$A13)>0, 8,"") | M13: =sum(C13:L13) -> 6.25 | N13: =IF(OR(B13="Sat", B13="Sun"), "", 8) -> 8 | P13: 0.41666667 | Q13: 0.67708333 | R13: =(Q13-P13)*24 -> 6.25
A14: =A13+1 -> 46120 | B14: =text(A14,"ddd") -> Wed | C14: 8.5 | G14: =IF(COUNTIF(Holidays!$A$2:$A$12,$A14)>0, 8,"") | M14: =sum(C14:L14) -> 8.5 | N14: =IF(OR(B14="Sat", B14="Sun"), "", 8) -> 8 | P14: 0.36458333 | Q14: 0.71875 | R14: =(Q14-P14)*24 -> 8.5
A15: =A14+1 -> 46121 | B15: =text(A15,"ddd") -> Thu | C15: 9.75 | G15: =IF(COUNTIF(Holidays!$A$2:$A$12,$A15)>0, 8,"") | M15: =sum(C15:L15) -> 9.75 | N15: =IF(OR(B15="Sat", B15="Sun"), "", 8) -> 8 | P15: 0.32291667 | Q15: 0.72916667 | R15: =(Q15-P15)*24 -> 9.75
A16: =A15+1 -> 46122 | B16: =text(A16,"ddd") -> Fri | C16: 6 | G16: =IF(COUNTIF(Holidays!$A$2:$A$12,$A16)>0, 8,"") | M16: =sum(C16:L16) -> 6 | N16: =IF(OR(B16="Sat", B16="Sun"), "", 8) -> 8 | P16: 0.34375 | Q16: 0.59375 | R16: =(Q16-P16)*24 -> 6
A17: =A16+1 -> 46123 | B17: =text(A17,"ddd") -> Sat | G17: =IF(COUNTIF(Holidays!$A$2:$A$12,$A17)>0, 8,"") | N17: =IF(OR(B17="Sat", B17="Sun"), "", 8) | P17: - | Q17: - | R17: -
A18: =A17+1 -> 46124 | B18: =text(A18,"ddd") -> Sun | G18: =IF(COUNTIF(Holidays!$A$2:$A$12,$A18)>0, 8,"") | N18: =IF(OR(B18="Sat", B18="Sun"), "", 8) | P18: - | Q18: - | R18: -
A19: =A18+1 -> 46125 | B19: =text(A19,"ddd") -> Mon | C19: 9.5 | G19: =IF(COUNTIF(Holidays!$A$2:$A$12,$A19)>0, 8,"") | M19: =sum(C19:L19) -> 9.5 | N19: =IF(OR(B19="Sat", B19="Sun"), "", 8) -> 8 | P19: 0.33333333 | Q19: 0.72916667 | R19: =(Q19-P19)*24 -> 9.5
A20: =A19+1 -> 46126 | B20: =text(A20,"ddd") -> Tue | C20: 9 | D20: 0.5 | G20: =IF(COUNTIF(Holidays!$A$2:$A$12,$A20)>0, 8,"") | M20: =sum(C20:L20) -> 9.5 | N20: =IF(OR(B20="Sat", B20="Sun"), "", 8) -> 8 | P20: 0.33333333 | Q20: 0.72916667 | R20: =(Q20-P20)*24 -> 9.5
A21: =A20+1 -> 46127 | B21: =text(A21,"ddd") -> Wed | C21: 8 | D21: 0.5 | G21: =IF(COUNTIF(Holidays!$A$2:$A$12,$A21)>0, 8,"") | M21: =sum(C21:L21) -> 8.5 | N21: =IF(OR(B21="Sat", B21="Sun"), "", 8) -> 8 | P21: 0.34375 | Q21: 0.69791667 | R21: =(Q21-P21)*24 -> 8.5
A22: Totals | C22: =sum(C7:C21) -> 88 | D22: =sum(D7:D21) -> 1 | E22: =sum(E7:E21) -> 0 | F22: =sum(F7:F21) -> 0 | G22: =sum(G7:G21) -> 0 | H22: =sum(H7:H21) -> 0 | I22: =sum(I7:I21) -> 0 | J22: =sum(J7:J21) -> 0 | ... N22: =sum(N7:N21) -> 88
A25: Pay Period 2 | B25: Weekday | C25: {=transpose('Time Types'!A2:A11)} -> Regular | D25: Bank-Save | E25: Bank-Use | F25: PTO | G25: Holiday | H25: Government | I25: F.Holiday | J25: Training | K25: Overhead | L25: Other | M25: Total | N25: Estimated
A26: =A21+1 -> 46128 | B26: =text(A26,"ddd") -> Thu | C26: 8 | D26: 1.25 | G26: =IF(COUNTIF(Holidays!$A$2:$A$12,$A26)>0, 8,"") | M26: =sum(C26:L26) -> 9.25 | N26: =IF(OR(B26="Sat", B26="Sun"), "", 8) -> 8 | P26: 0.36458333 | Q26: 0.75 | R26: =(Q26-P26)*24 -> 9.25
A27: =A26+1 -> 46129 | B27: =text(A27,"ddd") -> Fri | C27: 8 | G27: =IF(COUNTIF(Holidays!$A$2:$A$12,$A27)>0, 8,"") | M27: =sum(C27:L27) -> 8 | N27: =IF(OR(B27="Sat", B27="Sun"), "", 8) -> 8 | P27: 0.35416667 | Q27: 0.6875 | R27: =(Q27-P27)*24 -> 8
A28: =A27+1 -> 46130 | B28: =text(A28,"ddd") -> Sat | G28: =IF(COUNTIF(Holidays!$A$2:$A$12,$A28)>0, 8,"") | N28: =IF(OR(B28="Sat", B28="Sun"), "", 8) | P28: - | Q28: - | R28: -
A29: =A28+1 -> 46131 | B29: =text(A29,"ddd") -> Sun | G29: =IF(COUNTIF(Holidays!$A$2:$A$12,$A29)>0, 8,"") | N29: =IF(OR(B29="Sat", B29="Sun"), "", 8) | P29: - | Q29: - | R29: -
A30: =A29+1 -> 46132 | B30: =text(A30,"ddd") -> Mon | C30: 9 | G30: =IF(COUNTIF(Holidays!$A$2:$A$12,$A30)>0, 8,"") | M30: =sum(C30:L30) -> 9 | N30: =IF(OR(B30="Sat", B30="Sun"), "", 8) -> 8 | P30: 0.35416667 | Q30: 0.72916667 | R30: =(Q30-P30)*24 -> 9
A31: =A30+1 -> 46133 | B31: =text(A31,"ddd") -> Tue | C31: 7 | G31: =IF(COUNTIF(Holidays!$A$2:$A$12,$A31)>0, 8,"") | L31: 0.5 | M31: =sum(C31:L31) -> 7.5 | N31: =IF(OR(B31="Sat", B31="Sun"), "", 8) -> 8 | P31: 0.40625 | Q31: 0.71875 | R31: =(Q31-P31)*24+0.5 -> 8 | S31: =0.5 -> 0.5
A32: =A31+1 -> 46134 | B32: =text(A32,"ddd") -> Wed | C32: 8 | G32: =IF(COUNTIF(Holidays!$A$2:$A$12,$A32)>0, 8,"") | M32: =sum(C32:L32) -> 8 | N32: =IF(OR(B32="Sat", B32="Sun"), "", 8) -> 8 | P32: 0.36458333 | Q32: 0.69791667 | R32: =(Q32-P32)*24 -> 8
A33: =A32+1 -> 46135 | B33: =text(A33,"ddd") -> Thu | C33: 6.25 | G33: =IF(COUNTIF(Holidays!$A$2:$A$12,$A33)>0, 8,"") | M33: =sum(C33:L33) -> 6.25 | N33: =IF(OR(B33="Sat", B33="Sun"), "", 8) -> 8 | P33: 0.34375 | Q33: 0.54166667 | R33: =(Q33-P33)*24+1.5 -> 6.25
A34: =A33+1 -> 46136 | B34: =text(A34,"ddd") -> Fri | C34: 8.75 | G34: =IF(COUNTIF(Holidays!$A$2:$A$12,$A34)>0, 8,"") | M34: =sum(C34:L34) -> 8.75 | N34: =IF(OR(B34="Sat", B34="Sun"), "", 8) -> 8 | P34: 0.30208333 | Q34: 0.66666667 | R34: =(Q34-P34)*24 -> 8.75
A35: =A34+1 -> 46137 | B35: =text(A35,"ddd") -> Sat | G35: =IF(COUNTIF(Holidays!$A$2:$A$12,$A35)>0, 8,"") | N35: =IF(OR(B35="Sat", B35="Sun"), "", 8) | P35: - | Q35: - | R35: -
A36: =A35+1 -> 46138 | B36: =text(A36,"ddd") -> Sun | G36: =IF(COUNTIF(Holidays!$A$2:$A$12,$A36)>0, 8,"") | N36: =IF(OR(B36="Sat", B36="Sun"), "", 8) | P36: - | Q36: - | R36: -
A37: =A36+1 -> 46139 | B37: =text(A37,"ddd") -> Mon | C37: 8.5 | G37: =IF(COUNTIF(Holidays!$A$2:$A$12,$A37)>0, 8,"") | M37: =sum(C37:L37) -> 8.5 | N37: =IF(OR(B37="Sat", B37="Sun"), "", 8) -> 8 | P37: 0.34375 | Q37: 0.69791667 | R37: =(Q37-P37)*24 -> 8.5
A38: =A37+1 -> 46140 | B38: =text(A38,"ddd") -> Tue | C38: 8 | G38: =IF(COUNTIF(Holidays!$A$2:$A$12,$A38)>0, 8,"") | M38: =sum(C38:L38) -> 8 | N38: =IF(OR(B38="Sat", B38="Sun"), "", 8) -> 8 | P38: 0.375 | Q38: 0.70833333 | R38: =(Q38-P38)*24 -> 8
A39: =A38+1 -> 46141 | B39: =text(A39,"ddd") -> Wed | C39: 8 | G39: =IF(COUNTIF(Holidays!$A$2:$A$12,$A39)>0, 8,"") | M39: =sum(C39:L39) -> 8 | N39: =IF(OR(B39="Sat", B39="Sun"), "", 8) -> 8 | P39: 0.35416667 | Q39: 0.6875 | R39: =(Q39-P39)*24 -> 8
A40: =A39+1 -> 46142 | B40: =text(A40,"ddd") -> Thu | C40: 8 | G40: =IF(COUNTIF(Holidays!$A$2:$A$12,$A40)>0, 8,"") | M40: =sum(C40:L40) -> 8 | N40: =IF(OR(B40="Sat", B40="Sun"), "", 8) -> 8 | P40: 0.375 | Q40: 0.70833333 | R40: =(Q40-P40)*24 -> 8
G41: =IF(COUNTIF(Holidays!$A$2:$A$12,$A41)>0, 8,"")
A42: Totals | C42: =sum(C26:C41) -> 87.5 | D42: =sum(D26:D41) -> 1.25 | E42: =sum(E26:E41) -> 0 | F42: =sum(F26:F41) -> 0 | G42: =sum(G26:G41) -> 0 | H42: =sum(H26:H41) -> 0 | I42: =sum(I26:I41) -> 0 | J42: =sum(J26:J41) -> 0 | ... N42: =sum(N26:N41) -> 88 | R42: =sum(R25:R40) -> 89.75

Sheet May 26
A1: May | B1: PTO Totals | C1: Bank Totals | D1: F.Holiday Total | E1: Training Total
A2: Start of Month | B2: {=INDIRECT(TEXT(EDATE(DATE(2026, MATCH($A$1, {"January","February","March","April","May","June","July","August","September","October","November","December"}, 0), 1), -1), "mmm") & " 26!B4")} -> 61.5 | C2: {=INDIRECT(TEXT(EDATE(DATE(2026, MATCH($A$1, {"January","February","March","April","May","June","July","August","September","October","November","December"}, 0), 1), -1), "mmm") & " 26!C4")} -> 2.25 | D2: {=INDIRECT(TEXT(EDATE(DATE(2026, MATCH($A$1, {"January","February","March","April","May","June","July","August","September","October","November","December"}, 0), 1), -1), "mmm") & " 26!D4")} -> 8 | E2: {=INDIRECT(TEXT(EDATE(DATE(2026, MATCH($A$1, {"January","February","March","April","May","June","July","August","September","October","November","December"}, 0), 1), -1), "mmm") & " 26!E4")} -> 40 | G2: Earning Rate | H2: ='START HERE'!B6 -> 5
A3: End of Period 1 | B3: =B2+H2-F22 -> 66.5 | C3: =C2+D22-E22 -> 2.25 | D3: =D2-I22 -> 8 | E3: =E2-J22 -> 40
A4: End of Period 2 | B4: =B3+H2-F42 -> 71.5 | C4: =C3+D42-E42 -> 5.25 | D4: =D3-I42 -> 8 | E4: =E3-J42 -> 40
P5: IN | Q5: OUT | R5: Duration
A6: Pay Period 1 | B6: Weekday | C6: {=TRANSPOSE('Time Types'!A2:A11)} -> Regular | D6: Bank-Save | E6: Bank-Use | F6: PTO | G6: Holiday | H6: Government | I6: F.Holiday | J6: Training | K6: Overhead | L6: Other | M6: Total | N6: Estimated
A7: =DATE(2026, MONTH(DATEVALUE($A$1 & " 1")), 1) -> 46143 | B7: =text(A7,"ddd") -> Fri | C7: 7 | G7: =IF(COUNTIF(Holidays!$A$2:$A$12,$A7)>0, 8,"") | M7: =IF(OR(B7="Sat", B7="Sun"), "", sum(C7:J7)) -> 7 | N7: =IF(OR(B7="Sat", B7="Sun"), "", 8) -> 8 | P7: 0.38541667 | Q7: 0.67708333 | R7: =(Q7-P7)*24 -> 7
A8: =A7+1 -> 46144 | B8: =text(A8,"ddd") -> Sat | G8: =IF(COUNTIF(Holidays!$A$2:$A$12,$A8)>0, 8,"") | M8: =IF(OR(B8="Sat", B8="Sun"), "", sum(C8:J8)) | N8: =IF(OR(B8="Sat", B8="Sun"), "", 8) | P8: - | Q8: - | R8: -
A9: =A8+1 -> 46145 | B9: =text(A9,"ddd") -> Sun | G9: =IF(COUNTIF(Holidays!$A$2:$A$12,$A9)>0, 8,"") | M9: =IF(OR(B9="Sat", B9="Sun"), "", sum(C9:J9)) | N9: =IF(OR(B9="Sat", B9="Sun"), "", 8) | P9: - | Q9: - | R9: -
A10: =A9+1 -> 46146 | B10: =text(A10,"ddd") -> Mon | C10: 8.5 | G10: =IF(COUNTIF(Holidays!$A$2:$A$12,$A10)>0, 8,"") | M10: =IF(OR(B10="Sat", B10="Sun"), "", sum(C10:J10)) -> 8.5 | N10: =IF(OR(B10="Sat", B10="Sun"), "", 8) -> 8 | P10: 0.34375 | Q10: 0.70833333 | R10: =(Q10-P10)*24 -> 8.75
A11: =A10+1 -> 46147 | B11: =text(A11,"ddd") -> Tue | C11: 9 | G11: =IF(COUNTIF(Holidays!$A$2:$A$12,$A11)>0, 8,"") | M11: =IF(OR(B11="Sat", B11="Sun"), "", sum(C11:J11)) -> 9 | N11: =IF(OR(B11="Sat", B11="Sun"), "", 8) -> 8 | P11: 0.35416667 | Q11: 0.72916667 | R11: =(Q11-P11)*24 -> 9
A12: =A11+1 -> 46148 | B12: =text(A12,"ddd") -> Wed | C12: 8 | G12: =IF(COUNTIF(Holidays!$A$2:$A$12,$A12)>0, 8,"") | M12: =IF(OR(B12="Sat", B12="Sun"), "", sum(C12:J12)) -> 8 | N12: =IF(OR(B12="Sat", B12="Sun"), "", 8) -> 8 | P12: 0.33333333 | Q12: 0.70833333 | R12: =(Q12-P12)*24-1 -> 8
A13: =A12+1 -> 46149 | B13: =text(A13,"ddd") -> Thu | C13: 8.5 | G13: =IF(COUNTIF(Holidays!$A$2:$A$12,$A13)>0, 8,"") | M13: =IF(OR(B13="Sat", B13="Sun"), "", sum(C13:J13)) -> 8.5 | N13: =IF(OR(B13="Sat", B13="Sun"), "", 8) -> 8 | P13: 0.36458333 | Q13: 0.70833333 | R13: =(Q13-P13)*24 -> 8.25
A14: =A13+1 -> 46150 | B14: =text(A14,"ddd") -> Fri | C14: 4 | G14: =IF(COUNTIF(Holidays!$A$2:$A$12,$A14)>0, 8,"") | M14: =IF(OR(B14="Sat", B14="Sun"), "", sum(C14:J14)) -> 4 | N14: =IF(OR(B14="Sat", B14="Sun"), "", 8) -> 8 | P14: 0.33333333 | Q14: 0.5 | R14: =(Q14-P14)*24 -> 4
A15: =A14+1 -> 46151 | B15: =text(A15,"ddd") -> Sat | G15: =IF(COUNTIF(Holidays!$A$2:$A$12,$A15)>0, 8,"") | M15: =IF(OR(B15="Sat", B15="Sun"), "", sum(C15:J15)) | N15: =IF(OR(B15="Sat", B15="Sun"), "", 8) | P15: - | Q15: - | R15: -
A16: =A15+1 -> 46152 | B16: =text(A16,"ddd") -> Sun | G16: =IF(COUNTIF(Holidays!$A$2:$A$12,$A16)>0, 8,"") | M16: =IF(OR(B16="Sat", B16="Sun"), "", sum(C16:J16)) | N16: =IF(OR(B16="Sat", B16="Sun"), "", 8) | P16: - | Q16: - | R16: -
A17: =A16+1 -> 46153 | B17: =text(A17,"ddd") -> Mon | C17: 10 | G17: =IF(COUNTIF(Holidays!$A$2:$A$12,$A17)>0, 8,"") | M17: =IF(OR(B17="Sat", B17="Sun"), "", sum(C17:J17)) -> 10 | N17: =IF(OR(B17="Sat", B17="Sun"), "", 8) -> 8 | P17: 0.32291667 | Q17: 0.73958333 | R17: =(Q17-P17)*24 -> 10
A18: =A17+1 -> 46154 | B18: =text(A18,"ddd") -> Tue | C18: 8.25 | G18: =IF(COUNTIF(Holidays!$A$2:$A$12,$A18)>0, 8,"") | M18: =IF(OR(B18="Sat", B18="Sun"), "", sum(C18:J18)) -> 8.25 | N18: =IF(OR(B18="Sat", B18="Sun"), "", 8) -> 8 | P18: 0.30208333 | Q18: 0.64583333 | R18: =(Q18-P18)*24 -> 8.25
A19: =A18+1 -> 46155 | B19: =text(A19,"ddd") -> Wed | C19: 8.5 | G19: =IF(COUNTIF(Holidays!$A$2:$A$12,$A19)>0, 8,"") | M19: =IF(OR(B19="Sat", B19="Sun"), "", sum(C19:J19)) -> 8.5 | N19: =IF(OR(B19="Sat", B19="Sun"), "", 8) -> 8 | P19: 0.34375 | Q19: 0.69791667 | R19: =(Q19-P19)*24 -> 8.5
A20: =A19+1 -> 46156 | B20: =text(A20,"ddd") -> Thu | C20: 8.5 | G20: =IF(COUNTIF(Holidays!$A$2:$A$12,$A20)>0, 8,"") | M20: =IF(OR(B20="Sat", B20="Sun"), "", sum(C20:J20)) -> 8.5 | N20: =IF(OR(B20="Sat", B20="Sun"), "", 8) -> 8 | P20: 0.29166667 | Q20: 0.64583333 | R20: =(Q20-P20)*24 -> 8.5
A21: =A20+1 -> 46157 | B21: =text(A21,"ddd") -> Fri | C21: 7.75 | G21: =IF(COUNTIF(Holidays!$A$2:$A$12,$A21)>0, 8,"") | M21: =IF(OR(B21="Sat", B21="Sun"), "", sum(C21:J21)) -> 7.75 | N21: =IF(OR(B21="Sat", B21="Sun"), "", 8) -> 8 | P21: 0.34375 | Q21: 0.66666667 | R21: =(Q21-P21)*24 -> 7.75
A22: Totals | C22: =sum(C7:C21) -> 88 | D22: =sum(D7:D21) -> 0 | E22: =sum(E7:E21) -> 0 | F22: =sum(F7:F21) -> 0 | G22: =sum(G7:G21) -> 0 | H22: =sum(H7:H21) -> 0 | I22: =sum(I7:I21) -> 0 | J22: =sum(J7:J21) -> 0 | ... N22: =sum(N7:N21) -> 88
A25: Pay Period 2 | B25: Weekday | C25: {=transpose('Time Types'!A2:A11)} -> Regular | D25: Bank-Save | E25: Bank-Use | F25: PTO | G25: Holiday | H25: Government | I25: F.Holiday | J25: Training | K25: Overhead | L25: Other | M25: Total | N25: Estimated
A26: =A21+1 -> 46158 | B26: =text(A26,"ddd") -> Sat | G26: =IF(COUNTIF(Holidays!$A$2:$A$12,$A26)>0, 8,"") | M26: =IF(OR(B26="Sat", B26="Sun"), "", sum(C26:J26)) | N26: =IF(OR(B26="Sat", B26="Sun"), "", 8) | P26: - | Q26: - | R26: -
A27: =A26+1 -> 46159 | B27: =text(A27,"ddd") -> Sun | G27: =IF(COUNTIF(Holidays!$A$2:$A$12,$A27)>0, 8,"") | M27: =IF(OR(B27="Sat", B27="Sun"), "", sum(C27:J27)) | N27: =IF(OR(B27="Sat", B27="Sun"), "", 8) | P27: - | Q27: - | R27: -
A28: =A27+1 -> 46160 | B28: =text(A28,"ddd") -> Mon | C28: 8 | D28: 1.25 | G28: =IF(COUNTIF(Holidays!$A$2:$A$12,$A28)>0, 8,"") | M28: =IF(OR(B28="Sat", B28="Sun"), "", sum(C28:J28)) -> 9.25 | N28: =IF(OR(B28="Sat", B28="Sun"), "", 8) -> 8 | P28: 0.33333333 | Q28: 0.71875 | R28: =(Q28-P28)*24 -> 9.25
A29: =A28+1 -> 46161 | B29: =text(A29,"ddd") -> Tue | C29: 8 | D29: 0.75 | G29: =IF(COUNTIF(Holidays!$A$2:$A$12,$A29)>0, 8,"") | M29: =IF(OR(B29="Sat", B29="Sun"), "", sum(C29:J29)) -> 8.75 | N29: =IF(OR(B29="Sat", B29="Sun"), "", 8) -> 8 | P29: 0.32638889 | Q29: 0.69097222 | R29: =(Q29-P29)*24 -> 8.75
A30: =A29+1 -> 46162 | B30: =text(A30,"ddd") -> Wed | C30: 8 | G30: =IF(COUNTIF(Holidays!$A$2:$A$12,$A30)>0, 8,"") | M30: =IF(OR(B30="Sat", B30="Sun"), "", sum(C30:J30)) -> 8 | N30: =IF(OR(B30="Sat", B30="Sun"), "", 8) -> 8 | P30: 0.37847222 | Q30: 0.71180556 | R30: =(Q30-P30)*24 -> 8
A31: =A30+1 -> 46163 | B31: =text(A31,"ddd") -> Thu | C31: 8 | D31: 0.5 | G31: =IF(COUNTIF(Holidays!$A$2:$A$12,$A31)>0, 8,"") | M31: =IF(OR(B31="Sat", B31="Sun"), "", sum(C31:J31)) -> 8.5 | N31: =IF(OR(B31="Sat", B31="Sun"), "", 8) -> 8 | P31: 0.35416667 | Q31: 0.70833333 | R31: =(Q31-P31)*24 -> 8.5
A32: =A31+1 -> 46164 | B32: =text(A32,"ddd") -> Fri | C32: 7 | G32: =IF(COUNTIF(Holidays!$A$2:$A$12,$A32)>0, 8,"") | H32: 1 | M32: =IF(OR(B32="Sat", B32="Sun"), "", sum(C32:J32)) -> 8 | N32: =IF(OR(B32="Sat", B32="Sun"), "", 8) -> 8 | P32: 0.34375 | Q32: 0.63541667 | R32: =(Q32-P32)*24+1 -> 8
A33: =A32+1 -> 46165 | B33: =text(A33,"ddd") -> Sat | G33: =IF(COUNTIF(Holidays!$A$2:$A$12,$A33)>0, 8,"") | M33: =IF(OR(B33="Sat", B33="Sun"), "", sum(C33:J33)) | N33: =IF(OR(B33="Sat", B33="Sun"), "", 8) | P33: - | Q33: - | R33: -
A34: =A33+1 -> 46166 | B34: =text(A34,"ddd") -> Sun | G34: =IF(COUNTIF(Holidays!$A$2:$A$12,$A34)>0, 8,"") | M34: =IF(OR(B34="Sat", B34="Sun"), "", sum(C34:J34)) | N34: =IF(OR(B34="Sat", B34="Sun"), "", 8) | P34: - | Q34: - | R34: -
A35: =A34+1 -> 46167 | B35: =text(A35,"ddd") -> Mon | G35: =IF(COUNTIF(Holidays!$A$2:$A$12,$A35)>0, 8,"") -> 8 | M35: =IF(OR(B35="Sat", B35="Sun"), "", sum(C35:J35)) -> 8 | N35: =IF(OR(B35="Sat", B35="Sun"), "", 8) -> 8 | P35: 0.33333333 | Q35: 0.66666667 | R35: =(Q35-P35)*24 -> 8
A36: =A35+1 -> 46168 | B36: =text(A36,"ddd") -> Tue | C36: 8 | D36: 0.5 | G36: =IF(COUNTIF(Holidays!$A$2:$A$12,$A36)>0, 8,"") | M36: =IF(OR(B36="Sat", B36="Sun"), "", sum(C36:J36)) -> 8.5 | N36: =IF(OR(B36="Sat", B36="Sun"), "", 8) -> 8 | P36: 0.36805556 | Q36: 0.72222222 | R36: =(Q36-P36)*24 -> 8.5
A37: =A36+1 -> 46169 | B37: =text(A37,"ddd") -> Wed | C37: 8 | G37: =IF(COUNTIF(Holidays!$A$2:$A$12,$A37)>0, 8,"") | M37: =IF(OR(B37="Sat", B37="Sun"), "", sum(C37:J37)) -> 8 | N37: =IF(OR(B37="Sat", B37="Sun"), "", 8) -> 8 | P37: 0.34375 | Q37: 0.67708333 | R37: =(Q37-P37)*24 -> 8
A38: =A37+1 -> 46170 | B38: =text(A38,"ddd") -> Thu | C38: 8.5 | G38: =IF(COUNTIF(Holidays!$A$2:$A$12,$A38)>0, 8,"") | M38: =IF(OR(B38="Sat", B38="Sun"), "", sum(C38:J38)) -> 8.5 | N38: =IF(OR(B38="Sat", B38="Sun"), "", 8) -> 8 | P38: 0.33333333 | Q38: 0.6875 | R38: =(Q38-P38)*24 -> 8.5
A39: =A38+1 -> 46171 | B39: =text(A39,"ddd") -> Fri | C39: 7.5 | G39: =IF(COUNTIF(Holidays!$A$2:$A$12,$A39)>0, 8,"") | M39: =IF(OR(B39="Sat", B39="Sun"), "", sum(C39:J39)) -> 7.5 | N39: =IF(OR(B39="Sat", B39="Sun"), "", 8) -> 8 | P39: 0.33333333 | Q39: 0.6875 | R39: =(Q39-P39)*24 -> 8.5
A40: =A39+1 -> 46172 | B40: =text(A40,"ddd") -> Sat | G40: =IF(COUNTIF(Holidays!$A$2:$A$12,$A40)>0, 8,"") | M40: =IF(OR(B40="Sat", B40="Sun"), "", sum(C40:J40)) | N40: =IF(OR(B40="Sat", B40="Sun"), "", 8)
A41: =A40+1 -> 46173 | B41: =text(A41,"ddd") -> Sun | G41: =IF(COUNTIF(Holidays!$A$2:$A$12,$A41)>0, 8,"") | M41: =IF(OR(B41="Sat", B41="Sun"), "", sum(C41:J41)) | N41: =IF(OR(B41="Sat", B41="Sun"), "", 8)
A42: Totals | C42: =sum(C26:C41) -> 71 | D42: =sum(D26:D41) -> 3 | E42: =sum(E26:E41) -> 0 | F42: =sum(F26:F41) -> 0 | G42: =sum(G26:G41) -> 8 | H42: =sum(H26:H41) -> 1 | I42: =sum(I26:I41) -> 0 | J42: =sum(J26:J41) -> 0 | ... N42: =sum(N26:N41) -> 80 | R42: =sum(R25:R40) -> 84

Sheet Jun 26
A1: June | B1: PTO Totals | C1: Bank Totals | D1: F.Holiday Total | E1: Training Total
A2: Start of Month | B2: {=INDIRECT(TEXT(EDATE(DATE(2026, MATCH($A$1, {"January","February","March","April","May","June","July","August","September","October","November","December"}, 0), 1), -1), "mmm") & " 26!B4")} -> 71.5 | C2: {=INDIRECT(TEXT(EDATE(DATE(2026, MATCH($A$1, {"January","February","March","April","May","June","July","August","September","October","November","December"}, 0), 1), -1), "mmm") & " 26!C4")} -> 5.25 | D2: {=INDIRECT(TEXT(EDATE(DATE(2026, MATCH($A$1, {"January","February","March","April","May","June","July","August","September","October","November","December"}, 0), 1), -1), "mmm") & " 26!D4")} -> 8 | E2: {=INDIRECT(TEXT(EDATE(DATE(2026, MATCH($A$1, {"January","February","March","April","May","June","July","August","September","October","November","December"}, 0), 1), -1), "mmm") & " 26!E4")} -> 40 | G2: Earning Rate | H2: ='START HERE'!B6 -> 5
A3: End of Period 1 | B3: =B2+H2-F22 -> 76.5 | C3: =C2+D22-E22 -> 7.25 | D3: =D2-I22 -> 8 | E3: =E2-J22 -> 40
A4: End of Period 2 | B4: =B3+H2-F42 -> 73.5 | C4: =C3+D42-E42 -> 1.75 | D4: =D3-I42 -> 8 | E4: =E3-J42 -> 40
P5: IN | Q5: OUT | R5: Duration | S5: IR | T5: IN | U5: OUT | V5: DURATION
A6: Pay Period 1 | B6: Weekday | C6: {=TRANSPOSE('Time Types'!A2:A11)} -> Regular | D6: Bank-Save | E6: Bank-Use | F6: PTO | G6: Holiday | H6: Government | I6: F.Holiday | J6: Training | K6: Overhead | L6: Other | M6: Total | N6: Estimated | O6: AC
A7: =DATE(2026, MONTH(DATEVALUE($A$1 & " 1")), 1) -> 46174 | B7: =text(A7,"ddd") -> Mon | C7: 8.5 | G7: =IF(COUNTIF(Holidays!$A$2:$A$12,$A7)>0, 8,"") | M7: =IF(OR(B7="Sat", B7="Sun"), "", sum(C7:J7)) -> 8.5 | N7: =IF(OR(B7="Sat", B7="Sun"), "", 8) -> 8 | P7: 0.36458333 | Q7: 0.71875 | R7: =(Q7-P7)*24 -> 8.5 | T7: 0.33333333 | U7: 0.33333333 | V7: =(U7-T7)*24 -> 0 | W7: pto?
A8: =A7+1 -> 46175 | B8: =text(A8,"ddd") -> Tue | C8: 7.5 | G8: =IF(COUNTIF(Holidays!$A$2:$A$12,$A8)>0, 8,"") | M8: =IF(OR(B8="Sat", B8="Sun"), "", sum(C8:J8)) -> 7.5 | N8: =IF(OR(B8="Sat", B8="Sun"), "", 8) -> 8 | P8: 0.28125 | Q8: 0.67708333 | R8: =(Q8-P8)*24-2 -> 7.5 | T8: 0.42708333 | U8: 0.67708333 | V8: =(U8-T8)*24 -> 6 | W8: unsure when left
A9: =A8+1 -> 46176 | B9: =text(A9,"ddd") -> Wed | C9: 8 | D9: 0.75 | G9: =IF(COUNTIF(Holidays!$A$2:$A$12,$A9)>0, 8,"") | M9: =IF(OR(B9="Sat", B9="Sun"), "", sum(C9:J9)) -> 8.75 | N9: =IF(OR(B9="Sat", B9="Sun"), "", 8) -> 8 | P9: 0.36458333 | Q9: 0.72916667 | R9: =(Q9-P9)*24 -> 8.75 | T9: 0.41666667 | U9: 0.72916667 | V9: =(U9-T9)*24 -> 7.5 | W9: out .5/unsure when left | X9: 2-230
A10: =A9+1 -> 46177 | B10: =text(A10,"ddd") -> Thu | C10: 8 | G10: =IF(COUNTIF(Holidays!$A$2:$A$12,$A10)>0, 8,"") | M10: =IF(OR(B10="Sat", B10="Sun"), "", sum(C10:J10)) -> 8 | N10: =IF(OR(B10="Sat", B10="Sun"), "", 8) -> 8 | P10: 0.37847222 | Q10: 0.71180556 | R10: =(Q10-P10)*24 -> 8 | T10: 0.42013889 | U10: 0.75 | V10: =(U10-T10)*24 -> 7.9166667 | W10: out .5/unsure when left | X10: 4:15-4:40
A11: =A10+1 -> 46178 | B11: =text(A11,"ddd") -> Fri | C11: 8 | G11: =IF(COUNTIF(Holidays!$A$2:$A$12,$A11)>0, 8,"") | M11: =IF(OR(B11="Sat", B11="Sun"), "", sum(C11:J11)) -> 8 | N11: =IF(OR(B11="Sat", B11="Sun"), "", 8) -> 8 | P11: 0.36458333 | Q11: 0.69791667 | R11: =(Q11-P11)*24 -> 8 | T11: 0.35416667 | U11: 0.64236111 | V11: =(U11-T11)*24 -> 6.9166667 | W11: out .25
A12: =A11+1 -> 46179 | B12: =text(A12,"ddd") -> Sat | G12: =IF(COUNTIF(Holidays!$A$2:$A$12,$A12)>0, 8,"") | M12: =IF(OR(B12="Sat", B12="Sun"), "", sum(C12:J12)) | N12: =IF(OR(B12="Sat", B12="Sun"), "", 8)
A13: =A12+1 -> 46180 | B13: =text(A13,"ddd") -> Sun | G13: =IF(COUNTIF(Holidays!$A$2:$A$12,$A13)>0, 8,"") | M13: =IF(OR(B13="Sat", B13="Sun"), "", sum(C13:J13)) | N13: =IF(OR(B13="Sat", B13="Sun"), "", 8)
A14: =A13+1 -> 46181 | B14: =text(A14,"ddd") -> Mon | C14: 8 | G14: =IF(COUNTIF(Holidays!$A$2:$A$12,$A14)>0, 8,"") | M14: =IF(OR(B14="Sat", B14="Sun"), "", sum(C14:J14)) -> 8 | N14: =IF(OR(B14="Sat", B14="Sun"), "", 8) -> 8 | P14: 0.375 | Q14: 0.70833333 | R14: =(Q14-P14)*24 -> 8 | T14: 0.42222222 | U14: 0.75 | V14: =(U14-T14)*24 -> 7.8666667 | W14: before 7
A15: =A14+1 -> 46182 | B15: =text(A15,"ddd") -> Tue | C15: 8 | G15: =IF(COUNTIF(Holidays!$A$2:$A$12,$A15)>0, 8,"") | M15: =IF(OR(B15="Sat", B15="Sun"), "", sum(C15:J15)) -> 8 | N15: =IF(OR(B15="Sat", B15="Sun"), "", 8) -> 8 | P15: 0.375 | Q15: 0.70833333 | R15: =(Q15-P15)*24 -> 8 | T15: 0.27083333 | U15: 0.75 | V15: =(U15-T15)*24 -> 11.5 | W15: before 7
A16: =A15+1 -> 46183 | B16: =text(A16,"ddd") -> Wed | C16: 7.5 | G16: =IF(COUNTIF(Holidays!$A$2:$A$12,$A16)>0, 8,"") | M16: =IF(OR(B16="Sat", B16="Sun"), "", sum(C16:J16)) -> 7.5 | N16: =IF(OR(B16="Sat", B16="Sun"), "", 8) -> 8 | P16: 0.38888889 | Q16: 0.70138889 | R16: =(Q16-P16)*24 -> 7.5 | T16: 0.27083333 | U16: 0.75 | V16: =(U16-T16)*24 -> 11.5 | W16: before 7
A17: =A16+1 -> 46184 | B17: =text(A17,"ddd") -> Thu | C17: 8.5 | G17: =IF(COUNTIF(Holidays!$A$2:$A$12,$A17)>0, 8,"") | M17: =IF(OR(B17="Sat", B17="Sun"), "", sum(C17:J17)) -> 8.5 | N17: =IF(OR(B17="Sat", B17="Sun"), "", 8) -> 8 | P17: 0.38541667 | Q17: 0.73958333 | R17: =(Q17-P17)*24 -> 8.5 | T17: 0.27083333 | U17: 0.69791667 | V17: =(U17-T17)*24 -> 10.25 | W17: before 7
A18: =A17+1 -> 46185 | B18: =text(A18,"ddd") -> Fri | C18: 8 | D18: 0.25 | G18: =IF(COUNTIF(Holidays!$A$2:$A$12,$A18)>0, 8,"") | M18: =IF(OR(B18="Sat", B18="Sun"), "", sum(C18:J18)) -> 8.25 | N18: =IF(OR(B18="Sat", B18="Sun"), "", 8) -> 8 | P18: 0.36458333 | Q18: 0.70833333 | R18: 8.25 | T18: 0.41666667 | U18: 0.75 | V18: =(U18-T18)*24 -> 8
A19: =A18+1 -> 46186 | B19: =text(A19,"ddd") -> Sat | G19: =IF(COUNTIF(Holidays!$A$2:$A$12,$A19)>0, 8,"") | M19: =IF(OR(B19="Sat", B19="Sun"), "", sum(C19:J19)) | N19: =IF(OR(B19="Sat", B19="Sun"), "", 8)
A20: =A19+1 -> 46187 | B20: =text(A20,"ddd") -> Sun | G20: =IF(COUNTIF(Holidays!$A$2:$A$12,$A20)>0, 8,"") | M20: =IF(OR(B20="Sat", B20="Sun"), "", sum(C20:J20)) | N20: =IF(OR(B20="Sat", B20="Sun"), "", 8)
A21: =A20+1 -> 46188 | B21: =text(A21,"ddd") -> Mon | C21: 8 | D21: 1 | G21: =IF(COUNTIF(Holidays!$A$2:$A$12,$A21)>0, 8,"") | M21: =IF(OR(B21="Sat", B21="Sun"), "", sum(C21:J21)) -> 9 | N21: =IF(OR(B21="Sat", B21="Sun"), "", 8) -> 8 | P21: 0.3125 | Q21: 0.6875 | R21: =(Q21-P21)*24 -> 9 | T21: 0.41666667 | U21: 0.75 | V21: =(U21-T21)*24 -> 8
A22: Totals | C22: =sum(C7:C21) -> 88 | D22: =sum(D7:D21) -> 2 | E22: =sum(E7:E21) -> 0 | F22: =sum(F7:F21) -> 0 | G22: =sum(G7:G21) -> 0 | H22: =sum(H7:H21) -> 0 | I22: =sum(I7:I21) -> 0 | J22: =sum(J7:J21) -> 0 | ... N22: =sum(N7:N21) -> 88 | R22: =sum(R7:R21) -> 90 | V22: =sum(V7:V21) -> 85.45
A25: Pay Period 2 | B25: Weekday | C25: {=transpose('Time Types'!A2:A11)} -> Regular | D25: Bank-Save | E25: Bank-Use | F25: PTO | G25: Holiday | H25: Government | I25: F.Holiday | J25: Training | K25: Overhead | L25: Other | M25: Total | N25: Estimated
A26: =A21+1 -> 46189 | B26: =text(A26,"ddd") -> Tue | C26: 8 | G26: =IF(COUNTIF(Holidays!$A$2:$A$12,$A26)>0, 8,"") | M26: =IF(OR(B26="Sat", B26="Sun"), "", sum(C26:J26)) -> 8 | N26: =IF(OR(B26="Sat", B26="Sun"), "", 8) -> 8 | P26: 0.375 | Q26: 0.70833333 | R26: =(Q26-P26)*24 -> 8 | T26: 0.33333333 | U26: 0.66666667 | V26: =(U26-T26)*24 -> 8 | W26: pto
A27: =A26+1 -> 46190 | B27: =text(A27,"ddd") -> Wed | C27: 8 | G27: =IF(COUNTIF(Holidays!$A$2:$A$12,$A27)>0, 8,"") | M27: =IF(OR(B27="Sat", B27="Sun"), "", sum(C27:J27)) -> 8 | N27: =IF(OR(B27="Sat", B27="Sun"), "", 8) -> 8 | P27: 0.33333333 | Q27: 0.66666667 | R27: =(Q27-P27)*24 -> 8 | T27: 0.33333333 | U27: 0.66666667 | V27: =(U27-T27)*24 -> 8 | W27: pto
A28: =A27+1 -> 46191 | B28: =text(A28,"ddd") -> Thu | F28: 8 | G28: =IF(COUNTIF(Holidays!$A$2:$A$12,$A28)>0, 8,"") | M28: =IF(OR(B28="Sat", B28="Sun"), "", sum(C28:J28)) -> 8 | N28: =IF(OR(B28="Sat", B28="Sun"), "", 8) -> 8 | P28: 0.33333333 | Q28: 0.66666667 | R28: =(Q28-P28)*24 -> 8 | T28: 0.33333333 | U28: 0.66666667 | V28: =(U28-T28)*24 -> 8 | W28: idk
A29: =A28+1 -> 46192 | B29: =text(A29,"ddd") -> Fri | G29: =IF(COUNTIF(Holidays!$A$2:$A$12,$A29)>0, 8,"") -> 8 | M29: =IF(OR(B29="Sat", B29="Sun"), "", sum(C29:J29)) -> 8 | N29: =IF(OR(B29="Sat", B29="Sun"), "", 8) -> 8 | P29: 0.33333333 | Q29: 0.66666667 | R29: =(Q29-P29)*24 -> 8 | T29: 0.33333333 | U29: 0.66666667 | V29: =(U29-T29)*24 -> 8 | W29: holiday
A30: =A29+1 -> 46193 | B30: =text(A30,"ddd") -> Sat | G30: =IF(COUNTIF(Holidays!$A$2:$A$12,$A30)>0, 8,"") | M30: =IF(OR(B30="Sat", B30="Sun"), "", sum(C30:J30)) | N30: =IF(OR(B30="Sat", B30="Sun"), "", 8)
A31: =A30+1 -> 46194 | B31: =text(A31,"ddd") -> Sun | G31: =IF(COUNTIF(Holidays!$A$2:$A$12,$A31)>0, 8,"") | M31: =IF(OR(B31="Sat", B31="Sun"), "", sum(C31:J31)) | N31: =IF(OR(B31="Sat", B31="Sun"), "", 8)
A32: =A31+1 -> 46195 | B32: =text(A32,"ddd") -> Mon | C32: 9 | G32: =IF(COUNTIF(Holidays!$A$2:$A$12,$A32)>0, 8,"") | M32: =IF(OR(B32="Sat", B32="Sun"), "", sum(C32:J32)) -> 9 | N32: =IF(OR(B32="Sat", B32="Sun"), "", 8) -> 8 | P32: 0.36458333 | Q32: 0.73958333 | R32: =(Q32-P32)*24 -> 9 | T32: 0.33333333 | U32: 0.66666667 | V32: =(U32-T32)*24 -> 8
A33: =A32+1 -> 46196 | B33: =text(A33,"ddd") -> Tue | C33: 9 | G33: =IF(COUNTIF(Holidays!$A$2:$A$12,$A33)>0, 8,"") | M33: =IF(OR(B33="Sat", B33="Sun"), "", sum(C33:J33)) -> 9 | N33: =IF(OR(B33="Sat", B33="Sun"), "", 8) -> 8 | P33: 0.35763889 | Q33: 0.73263889 | R33: =(Q33-P33)*24 -> 9 | T33: 0.33333333 | U33: 0.66666667 | V33: =(U33-T33)*24 -> 8
A34: =A33+1 -> 46197 | B34: =text(A34,"ddd") -> Wed | C34: 8 | G34: =IF(COUNTIF(Holidays!$A$2:$A$12,$A34)>0, 8,"") | M34: =IF(OR(B34="Sat", B34="Sun"), "", sum(C34:J34)) -> 8 | N34: =IF(OR(B34="Sat", B34="Sun"), "", 8) -> 8 | P34: 0.36458333 | Q34: 0.69791667 | R34: 8 | T34: 0.33333333 | U34: 0.66666667 | V34: =(U34-T34)*24 -> 8
A35: =A34+1 -> 46198 | B35: =text(A35,"ddd") -> Thu | C35: 8.75 | G35: =IF(COUNTIF(Holidays!$A$2:$A$12,$A35)>0, 8,"") | M35: =IF(OR(B35="Sat", B35="Sun"), "", sum(C35:J35)) -> 8.75 | N35: =IF(OR(B35="Sat", B35="Sun"), "", 8) -> 8 | P35: 0.375 | Q35: 0.73958333 | R35: =(Q35-P35)*24 -> 8.75 | T35: 0.33333333 | U35: 0.66666667 | V35: =(U35-T35)*24 -> 8
A36: =A35+1 -> 46199 | B36: =text(A36,"ddd") -> Fri | C36: 3.75 | E36: 4 | G36: =IF(COUNTIF(Holidays!$A$2:$A$12,$A36)>0, 8,"") | M36: =IF(OR(B36="Sat", B36="Sun"), "", sum(C36:J36)) -> 7.75 | N36: =IF(OR(B36="Sat", B36="Sun"), "", 8) -> 8 | P36: 0.34375 | Q36: 0.51041667 | R36: =(Q36-P36)*24 -> 4 | T36: 0.33333333 | U36: 0.66666667 | V36: =(U36-T36)*24 -> 8
A37: =A36+1 -> 46200 | B37: =text(A37,"ddd") -> Sat | G37: =IF(COUNTIF(Holidays!$A$2:$A$12,$A37)>0, 8,"") | M37: =IF(OR(B37="Sat", B37="Sun"), "", sum(C37:J37)) | N37: =IF(OR(B37="Sat", B37="Sun"), "", 8)
A38: =A37+1 -> 46201 | B38: =text(A38,"ddd") -> Sun | G38: =IF(COUNTIF(Holidays!$A$2:$A$12,$A38)>0, 8,"") | M38: =IF(OR(B38="Sat", B38="Sun"), "", sum(C38:J38)) | N38: =IF(OR(B38="Sat", B38="Sun"), "", 8)
A39: =A38+1 -> 46202 | B39: =text(A39,"ddd") -> Mon | C39: 4 | E39: 1.5 | G39: =IF(COUNTIF(Holidays!$A$2:$A$12,$A39)>0, 8,"") | M39: =IF(OR(B39="Sat", B39="Sun"), "", sum(C39:J39)) -> 5.5 | N39: =IF(OR(B39="Sat", B39="Sun"), "", 8) -> 8 | P39: 0.57291667 | Q39: 0.73958333 | R39: =(Q39-P39)*24 -> 4 | T39: 0.33333333 | U39: 0.66666667 | V39: =(U39-T39)*24 -> 8
A40: =A39+1 -> 46203 | B40: =text(A40,"ddd") -> Tue | C40: 8 | G40: =IF(COUNTIF(Holidays!$A$2:$A$12,$A40)>0, 8,"") | M40: =IF(OR(B40="Sat", B40="Sun"), "", sum(C40:J40)) -> 8 | N40: =IF(OR(B40="Sat", B40="Sun"), "", 8) -> 8 | P40: 0.3125 | Q40: 0.66666667 | R40: =(Q40-P40)*24 -> 8.5 | T40: 0.33333333 | U40: 0.66666667 | V40: =(U40-T40)*24 -> 8
G41: =IF(COUNTIF(Holidays!$A$2:$A$12,$A41)>0, 8,"")
A42: Totals | C42: =sum(C26:C41) -> 66.5 | D42: =sum(D26:D41) -> 0 | E42: =sum(E26:E41) -> 5.5 | F42: =sum(F26:F41) -> 8 | G42: =sum(G26:G41) -> 8 | H42: =sum(H26:H41) -> 0 | I42: =sum(I26:I41) -> 0 | J42: =sum(J26:J41) -> 0 | ... N42: =sum(N26:N41) -> 88 | R42: =sum(R25:R41) -> 83.25 | V42: =sum(V26:V41) -> 88

Sheet Jul 26
A1: July | B1: PTO Totals | C1: Bank Totals | D1: F.Holiday Total | E1: Training Total
A2: Start of Month | B2: {=INDIRECT(TEXT(EDATE(DATE(2026, MATCH($A$1, {"January","February","March","April","May","June","July","August","September","October","November","December"}, 0), 1), -1), "mmm") & " 26!B4")} -> 73.5 | C2: {=INDIRECT(TEXT(EDATE(DATE(2026, MATCH($A$1, {"January","February","March","April","May","June","July","August","September","October","November","December"}, 0), 1), -1), "mmm") & " 26!C4")} -> 1.75 | D2: {=INDIRECT(TEXT(EDATE(DATE(2026, MATCH($A$1, {"January","February","March","April","May","June","July","August","September","October","November","December"}, 0), 1), -1), "mmm") & " 26!D4")} -> 8 | E2: {=INDIRECT(TEXT(EDATE(DATE(2026, MATCH($A$1, {"January","February","March","April","May","June","July","August","September","October","November","December"}, 0), 1), -1), "mmm") & " 26!E4")} -> 40 | G2: Earning Rate | H2: ='START HERE'!B6 -> 5
A3: End of Period 1 | B3: =B2+H2-F22 -> 78.5 | C3: =C2+D22-E22 -> 7.5 | D3: =D2-I22 -> 8 | E3: =E2-J22 -> 40
A4: End of Period 2 | B4: =B3+H2-F42 -> 83.5 | C4: =C3+D42-E42 -> 11.5 | D4: =D3-I42 -> 8 | E4: =E3-J42 -> 40
P5: IN | Q5: OUT | R5: Duration
A6: Pay Period 1 | B6: Weekday | C6: {=TRANSPOSE('Time Types'!A2:A11)} -> Regular | D6: Bank-Save | E6: Bank-Use | F6: PTO | G6: Holiday | H6: Government | I6: F.Holiday | J6: Training | K6: Overhead | L6: Other | M6: Total | N6: Estimated
A7: =DATE(2026, MONTH(DATEVALUE($A$1 & " 1")), 1) -> 46204 | B7: =text(A7,"ddd") -> Wed | C7: 8 | G7: =IF(COUNTIF(Holidays!$A$2:$A$12,$A7)>0, 8,"") | M7: =IF(OR(B7="Sat", B7="Sun"), "", sum(C7:J7)) -> 8 | N7: =IF(OR(B7="Sat", B7="Sun"), "", 8) -> 8 | P7: 0.38541667 | Q7: 0.71875 | R7: =(Q7-P7)*24 -> 8
A8: =A7+1 -> 46205 | B8: =text(A8,"ddd") -> Thu | C8: 7 | G8: =IF(COUNTIF(Holidays!$A$2:$A$12,$A8)>0, 8,"") | H8: 1 | M8: =IF(OR(B8="Sat", B8="Sun"), "", sum(C8:J8)) -> 8 | N8: =IF(OR(B8="Sat", B8="Sun"), "", 8) -> 8 | P8: 0.375 | Q8: 0.66666667 | R8: =(Q8-P8)*24+1 -> 8 | S8: extra hour gov
A9: =A8+1 -> 46206 | B9: =text(A9,"ddd") -> Fri | G9: =IF(COUNTIF(Holidays!$A$2:$A$12,$A9)>0, 8,"") -> 8 | M9: =IF(OR(B9="Sat", B9="Sun"), "", sum(C9:J9)) -> 8 | N9: =IF(OR(B9="Sat", B9="Sun"), "", 8) -> 8 | P9: 0.33333333 | Q9: 0.66666667 | R9: =(Q9-P9)*24 -> 8
A10: =A9+1 -> 46207 | B10: =text(A10,"ddd") -> Sat | G10: =IF(COUNTIF(Holidays!$A$2:$A$12,$A10)>0, 8,"") | M10: =IF(OR(B10="Sat", B10="Sun"), "", sum(C10:J10)) | N10: =IF(OR(B10="Sat", B10="Sun"), "", 8)
A11: =A10+1 -> 46208 | B11: =text(A11,"ddd") -> Sun | G11: =IF(COUNTIF(Holidays!$A$2:$A$12,$A11)>0, 8,"") | M11: =IF(OR(B11="Sat", B11="Sun"), "", sum(C11:J11)) | N11: =IF(OR(B11="Sat", B11="Sun"), "", 8)
A12: =A11+1 -> 46209 | B12: =text(A12,"ddd") -> Mon | C12: 8 | D12: 2 | G12: =IF(COUNTIF(Holidays!$A$2:$A$12,$A12)>0, 8,"") | M12: =IF(OR(B12="Sat", B12="Sun"), "", sum(C12:J12)) -> 10 | N12: =IF(OR(B12="Sat", B12="Sun"), "", 8) -> 8 | P12: 0.36458333 | Q12: 0.73958333 | R12: =(Q12-P12)*24+1 -> 10 | S12: Extra hour 7-8pm
A13: =A12+1 -> 46210 | B13: =text(A13,"ddd") -> Tue | C13: 8.75 | G13: =IF(COUNTIF(Holidays!$A$2:$A$12,$A13)>0, 8,"") | M13: =IF(OR(B13="Sat", B13="Sun"), "", sum(C13:J13)) -> 8.75 | N13: =IF(OR(B13="Sat", B13="Sun"), "", 8) -> 8 | P13: 0.375 | Q13: 0.73958333 | R13: =(Q13-P13)*24 -> 8.75 | S13: extra .75
A14: =A13+1 -> 46211 | B14: =text(A14,"ddd") -> Wed | C14: 7.25 | G14: =IF(COUNTIF(Holidays!$A$2:$A$12,$A14)>0, 8,"") | M14: =IF(OR(B14="Sat", B14="Sun"), "", sum(C14:J14)) -> 7.25 | N14: =IF(OR(B14="Sat", B14="Sun"), "", 8) -> 8 | P14: 0.39583333 | Q14: 0.69791667 | R14: =(Q14-P14)*24 -> 7.25
A15: =A14+1 -> 46212 | B15: =text(A15,"ddd") -> Thu | C15: 8 | D15: 0.25 | G15: =IF(COUNTIF(Holidays!$A$2:$A$12,$A15)>0, 8,"") | M15: =IF(OR(B15="Sat", B15="Sun"), "", sum(C15:J15)) -> 8.25 | N15: =IF(OR(B15="Sat", B15="Sun"), "", 8) -> 8 | P15: 0.39583333 | Q15: 0.73958333 | R15: =(Q15-P15)*24 -> 8.25 | S15: extra .25
A16: =A15+1 -> 46213 | B16: =text(A16,"ddd") -> Fri | C16: 8 | G16: =IF(COUNTIF(Holidays!$A$2:$A$12,$A16)>0, 8,"") | M16: =IF(OR(B16="Sat", B16="Sun"), "", sum(C16:J16)) -> 8 | N16: =IF(OR(B16="Sat", B16="Sun"), "", 8) -> 8 | P16: 0.34375 | Q16: 0.67708333 | R16: =(Q16-P16)*24 -> 8
A17: =A16+1 -> 46214 | B17: =text(A17,"ddd") -> Sat | G17: =IF(COUNTIF(Holidays!$A$2:$A$12,$A17)>0, 8,"") | M17: =IF(OR(B17="Sat", B17="Sun"), "", sum(C17:J17)) | N17: =IF(OR(B17="Sat", B17="Sun"), "", 8)
A18: =A17+1 -> 46215 | B18: =text(A18,"ddd") -> Sun | G18: =IF(COUNTIF(Holidays!$A$2:$A$12,$A18)>0, 8,"") | M18: =IF(OR(B18="Sat", B18="Sun"), "", sum(C18:J18)) | N18: =IF(OR(B18="Sat", B18="Sun"), "", 8)
A19: =A18+1 -> 46216 | B19: =text(A19,"ddd") -> Mon | C19: 8 | D19: 2 | G19: =IF(COUNTIF(Holidays!$A$2:$A$12,$A19)>0, 8,"") | M19: =IF(OR(B19="Sat", B19="Sun"), "", sum(C19:J19)) -> 10 | N19: =IF(OR(B19="Sat", B19="Sun"), "", 8) -> 8 | P19: 0.25 | Q19: 0.66666667 | R19: =(Q19-P19)*24 -> 10 | S19: extra 2 hr
A20: =A19+1 -> 46217 | B20: =text(A20,"ddd") -> Tue | C20: 8 | D20: 0.5 | G20: =IF(COUNTIF(Holidays!$A$2:$A$12,$A20)>0, 8,"") | M20: =IF(OR(B20="Sat", B20="Sun"), "", sum(C20:J20)) -> 8.5 | N20: =IF(OR(B20="Sat", B20="Sun"), "", 8) -> 8 | P20: 0.375 | Q20: 0.72916667 | R20: =(Q20-P20)*24 -> 8.5 | S20: extra .5 hr
A21: =A20+1 -> 46218 | B21: =text(A21,"ddd") -> Wed | C21: 8 | D21: 1 | G21: =IF(COUNTIF(Holidays!$A$2:$A$12,$A21)>0, 8,"") | M21: =IF(OR(B21="Sat", B21="Sun"), "", sum(C21:J21)) -> 9 | N21: =IF(OR(B21="Sat", B21="Sun"), "", 8) -> 8 | P21: 0.32291667 | Q21: 0.69791667 | R21: =(Q21-P21)*24 -> 9 | S21: extra 1 hr
A22: Totals | C22: =sum(C7:C21) -> 79 | D22: =sum(D7:D21) -> 5.75 | E22: =sum(E7:E21) -> 0 | F22: =sum(F7:F21) -> 0 | G22: =sum(G7:G21) -> 8 | H22: =sum(H7:H21) -> 1 | I22: =sum(I7:I21) -> 0 | J22: =sum(J7:J21) -> 0 | ... N22: =sum(N7:N21) -> 88 | R22: =sum(R7:R21) -> 93.75
A25: Pay Period 2 | B25: Weekday | C25: {=transpose('Time Types'!A2:A11)} -> Regular | D25: Bank-Save | E25: Bank-Use | F25: PTO | G25: Holiday | H25: Government | I25: F.Holiday | J25: Training | K25: Overhead | L25: Other | M25: Total | N25: Estimated
A26: =A21+1 -> 46219 | B26: =text(A26,"ddd") -> Thu | C26: 8 | G26: =IF(COUNTIF(Holidays!$A$2:$A$12,$A26)>0, 8,"") | M26: =IF(OR(B26="Sat", B26="Sun"), "", sum(C26:J26)) -> 8 | N26: =IF(OR(B26="Sat", B26="Sun"), "", 8) -> 8 | P26: 0.38541667 | Q26: 0.71875 | R26: =(Q26-P26)*24 -> 8
A27: =A26+1 -> 46220 | B27: =text(A27,"ddd") -> Fri | C27: 8 | G27: =IF(COUNTIF(Holidays!$A$2:$A$12,$A27)>0, 8,"") | M27: =IF(OR(B27="Sat", B27="Sun"), "", sum(C27:J27)) -> 8 | N27: =IF(OR(B27="Sat", B27="Sun"), "", 8) -> 8 | P27: 0.35416667 | Q27: 0.6875 | R27: =(Q27-P27)*24 -> 8
A28: =A27+1 -> 46221 | B28: =text(A28,"ddd") -> Sat | G28: =IF(COUNTIF(Holidays!$A$2:$A$12,$A28)>0, 8,"") | M28: =IF(OR(B28="Sat", B28="Sun"), "", sum(C28:J28)) | N28: =IF(OR(B28="Sat", B28="Sun"), "", 8)
A29: =A28+1 -> 46222 | B29: =text(A29,"ddd") -> Sun | G29: =IF(COUNTIF(Holidays!$A$2:$A$12,$A29)>0, 8,"") | M29: =IF(OR(B29="Sat", B29="Sun"), "", sum(C29:J29)) | N29: =IF(OR(B29="Sat", B29="Sun"), "", 8)
A30: =A29+1 -> 46223 | B30: =text(A30,"ddd") -> Mon | C30: 8 | D30: 1 | G30: =IF(COUNTIF(Holidays!$A$2:$A$12,$A30)>0, 8,"") | M30: =IF(OR(B30="Sat", B30="Sun"), "", sum(C30:J30)) -> 9 | N30: =IF(OR(B30="Sat", B30="Sun"), "", 8) -> 8 | P30: 0.35416667 | Q30: 0.72916667 | R30: =(Q30-P30)*24 -> 9
A31: =A30+1 -> 46224 | B31: =text(A31,"ddd") -> Tue | C31: 8 | D31: 0.5 | G31: =IF(COUNTIF(Holidays!$A$2:$A$12,$A31)>0, 8,"") | M31: =IF(OR(B31="Sat", B31="Sun"), "", sum(C31:J31)) -> 8.5 | N31: =IF(OR(B31="Sat", B31="Sun"), "", 8) -> 8 | P31: 0.375 | Q31: 0.72916667 | R31: =(Q31-P31)*24 -> 8.5
A32: =A31+1 -> 46225 | B32: =text(A32,"ddd") -> Wed | C32: 8.5 | G32: =IF(COUNTIF(Holidays!$A$2:$A$12,$A32)>0, 8,"") | M32: =IF(OR(B32="Sat", B32="Sun"), "", sum(C32:J32)) -> 8.5 | N32: =IF(OR(B32="Sat", B32="Sun"), "", 8) -> 8 | P32: 0.34375 | Q32: 0.69791667 | R32: =(Q32-P32)*24 -> 8.5
A33: =A32+1 -> 46226 | B33: =text(A33,"ddd") -> Thu | C33: 6.5 | G33: =IF(COUNTIF(Holidays!$A$2:$A$12,$A33)>0, 8,"") | M33: =IF(OR(B33="Sat", B33="Sun"), "", sum(C33:J33)) -> 6.5 | N33: =IF(OR(B33="Sat", B33="Sun"), "", 8) -> 8 | P33: 0.36458333 | Q33: 0.63541667 | R33: =(Q33-P33)*24 -> 6.5
A34: =A33+1 -> 46227 | B34: =text(A34,"ddd") -> Fri | C34: 8 | G34: =IF(COUNTIF(Holidays!$A$2:$A$12,$A34)>0, 8,"") | M34: =IF(OR(B34="Sat", B34="Sun"), "", sum(C34:J34)) -> 8 | N34: =IF(OR(B34="Sat", B34="Sun"), "", 8) -> 8 | P34: 0.35416667 | Q34: 0.6875 | R34: =(Q34-P34)*24 -> 8
A35: =A34+1 -> 46228 | B35: =text(A35,"ddd") -> Sat | G35: =IF(COUNTIF(Holidays!$A$2:$A$12,$A35)>0, 8,"") | M35: =IF(OR(B35="Sat", B35="Sun"), "", sum(C35:J35)) | N35: =IF(OR(B35="Sat", B35="Sun"), "", 8)
A36: =A35+1 -> 46229 | B36: =text(A36,"ddd") -> Sun | G36: =IF(COUNTIF(Holidays!$A$2:$A$12,$A36)>0, 8,"") | M36: =IF(OR(B36="Sat", B36="Sun"), "", sum(C36:J36)) | N36: =IF(OR(B36="Sat", B36="Sun"), "", 8)
A37: =A36+1 -> 46230 | B37: =text(A37,"ddd") -> Mon | C37: 7.5 | G37: =IF(COUNTIF(Holidays!$A$2:$A$12,$A37)>0, 8,"") | M37: =IF(OR(B37="Sat", B37="Sun"), "", sum(C37:J37)) -> 7.5 | N37: =IF(OR(B37="Sat", B37="Sun"), "", 8) -> 8 | P37: 0.3125 | Q37: 0.625 | R37: =(Q37-P37)*24 -> 7.5
A38: =A37+1 -> 46231 | B38: =text(A38,"ddd") -> Tue | C38: 9 | D38: 0.75 | G38: =IF(COUNTIF(Holidays!$A$2:$A$12,$A38)>0, 8,"") | M38: =IF(OR(B38="Sat", B38="Sun"), "", sum(C38:J38)) -> 9.75 | N38: =IF(OR(B38="Sat", B38="Sun"), "", 8) -> 8 | P38: 0.33333333 | Q38: 0.73958333 | R38: =(Q38-P38)*24 -> 9.75
A39: =A38+1 -> 46232 | B39: =text(A39,"ddd") -> Wed | C39: 8.5 | G39: =IF(COUNTIF(Holidays!$A$2:$A$12,$A39)>0, 8,"") | M39: =IF(OR(B39="Sat", B39="Sun"), "", sum(C39:J39)) -> 8.5 | N39: =IF(OR(B39="Sat", B39="Sun"), "", 8) -> 8 | P39: 0.34375 | Q39: 0.69791667 | R39: =(Q39-P39)*24 -> 8.5
A40: =A39+1 -> 46233 | B40: =text(A40,"ddd") -> Thu | C40: 8 | D40: 0.25 | G40: =IF(COUNTIF(Holidays!$A$2:$A$12,$A40)>0, 8,"") | M40: =IF(OR(B40="Sat", B40="Sun"), "", sum(C40:J40)) -> 8.25 | N40: =IF(OR(B40="Sat", B40="Sun"), "", 8) -> 8 | P40: 0.38541667 | Q40: 0.75 | R40: =(Q40-P40)*24 -> 8.75
A41: =A40+1 -> 46234 | B41: =text(A41,"ddd") -> Fri | C41: 8 | D41: 1.5 | G41: =IF(COUNTIF(Holidays!$A$2:$A$12,$A41)>0, 8,"") | M41: =IF(OR(B41="Sat", B41="Sun"), "", sum(C41:J41)) -> 9.5 | N41: =IF(OR(B41="Sat", B41="Sun"), "", 8) -> 8 | P41: 0.3125 | Q41: 0.70833333 | R41: =(Q41-P41)*24 -> 9.5
A42: Totals | C42: =sum(C26:C41) -> 96 | D42: =sum(D26:D41) -> 4 | E42: =sum(E26:E41) -> 0 | F42: =sum(F26:F41) -> 0 | G42: =sum(G26:G41) -> 0 | H42: =sum(H26:H41) -> 0 | I42: =sum(I26:I41) -> 0 | J42: =sum(J26:J41) -> 0 | ... N42: =sum(N26:N41) -> 96 | R42: =sum(R26:R41) -> 100.5

Sheet Aug 26
A1: August | B1: PTO Totals | C1: Bank Totals | D1: F.Holiday Total | E1: Training Total
A2: Start of Month | B2: {=INDIRECT(TEXT(EDATE(DATE(2026, MATCH($A$1, {"January","February","March","April","May","June","July","August","September","October","November","December"}, 0), 1), -1), "mmm") & " 26!B4")} -> 83.5 | C2: {=INDIRECT(TEXT(EDATE(DATE(2026, MATCH($A$1, {"January","February","March","April","May","June","July","August","September","October","November","December"}, 0), 1), -1), "mmm") & " 26!C4")} -> 11.5 | D2: {=INDIRECT(TEXT(EDATE(DATE(2026, MATCH($A$1, {"January","February","March","April","May","June","July","August","September","October","November","December"}, 0), 1), -1), "mmm") & " 26!D4")} -> 8 | E2: {=INDIRECT(TEXT(EDATE(DATE(2026, MATCH($A$1, {"January","February","March","April","May","June","July","August","September","October","November","December"}, 0), 1), -1), "mmm") & " 26!E4")} -> 40 | G2: Earning Rate | H2: ='START HERE'!B6 -> 5
A3: End of Period 1 | B3: =B2+H2-F22 -> 88.5 | C3: =C2+D22-E22 -> 17.25 | D3: =D2-I22 -> 8 | E3: =E2-J22 -> 40
A4: End of Period 2 | B4: =B3+H2-F42 -> 72.5 | C4: =C3+D42-E42 -> 1.25 | D4: =D3-I42 -> 8 | E4: =E3-J42 -> 40
P5: IN | Q5: OUT | R5: Duration
A6: Pay Period 1 | B6: Weekday | C6: {=TRANSPOSE('Time Types'!A2:A11)} -> Regular | D6: Bank-Save | E6: Bank-Use | F6: PTO | G6: Holiday | H6: Government | I6: F.Holiday | J6: Training | K6: Overhead | L6: Other | M6: Total | N6: Estimated
A7: =DATE(2026, MONTH(DATEVALUE($A$1 & " 1")), 1) -> 46235 | B7: =text(A7,"ddd") -> Sat | G7: =IF(COUNTIF(Holidays!$A$2:$A$12,$A7)>0, 8,"") | M7: =IF(OR(B7="Sat", B7="Sun"), "", sum(C7:J7)) | N7: =IF(OR(B7="Sat", B7="Sun"), "", 8)
A8: =A7+1 -> 46236 | B8: =text(A8,"ddd") -> Sun | G8: =IF(COUNTIF(Holidays!$A$2:$A$12,$A8)>0, 8,"") | M8: =IF(OR(B8="Sat", B8="Sun"), "", sum(C8:J8)) | N8: =IF(OR(B8="Sat", B8="Sun"), "", 8)
A9: =A8+1 -> 46237 | B9: =text(A9,"ddd") -> Mon | C9: 8 | D9: 1.75 | G9: =IF(COUNTIF(Holidays!$A$2:$A$12,$A9)>0, 8,"") | M9: =IF(OR(B9="Sat", B9="Sun"), "", sum(C9:J9)) -> 9.75 | N9: =IF(OR(B9="Sat", B9="Sun"), "", 8) -> 8 | P9: 0.33333333 | Q9: 0.73958333 | R9: =(Q9-P9)*24 -> 9.75
A10: =A9+1 -> 46238 | B10: =text(A10,"ddd") -> Tue | C10: 8 | D10: 1 | G10: =IF(COUNTIF(Holidays!$A$2:$A$12,$A10)>0, 8,"") | M10: =IF(OR(B10="Sat", B10="Sun"), "", sum(C10:J10)) -> 9 | N10: =IF(OR(B10="Sat", B10="Sun"), "", 8) -> 8 | P10: 0.35416667 | Q10: 0.72916667 | R10: =(Q10-P10)*24 -> 9
A11: =A10+1 -> 46239 | B11: =text(A11,"ddd") -> Wed | C11: 8 | D11: 1.25 | G11: =IF(COUNTIF(Holidays!$A$2:$A$12,$A11)>0, 8,"") | M11: =IF(OR(B11="Sat", B11="Sun"), "", sum(C11:J11)) -> 9.25 | N11: =IF(OR(B11="Sat", B11="Sun"), "", 8) -> 8 | P11: 0.30555556 | Q11: 0.69097222 | R11: =(Q11-P11)*24 -> 9.25
A12: =A11+1 -> 46240 | B12: =text(A12,"ddd") -> Thu | C12: 8.5 | D12: 0.75 | G12: =IF(COUNTIF(Holidays!$A$2:$A$12,$A12)>0, 8,"") | M12: =IF(OR(B12="Sat", B12="Sun"), "", sum(C12:J12)) -> 9.25 | N12: =IF(OR(B12="Sat", B12="Sun"), "", 8) -> 8 | P12: 0.36458333 | Q12: 0.75 | R12: =(Q12-P12)*24 -> 9.25
A13: =A12+1 -> 46241 | B13: =text(A13,"ddd") -> Fri | C13: 7.5 | G13: =IF(COUNTIF(Holidays!$A$2:$A$12,$A13)>0, 8,"") | M13: =IF(OR(B13="Sat", B13="Sun"), "", sum(C13:J13)) -> 7.5 | N13: =IF(OR(B13="Sat", B13="Sun"), "", 8) -> 8 | P13: 0.34375 | Q13: 0.65625 | R13: =(Q13-P13)*24 -> 7.5
A14: =A13+1 -> 46242 | B14: =text(A14,"ddd") -> Sat | G14: =IF(COUNTIF(Holidays!$A$2:$A$12,$A14)>0, 8,"") | M14: =IF(OR(B14="Sat", B14="Sun"), "", sum(C14:J14)) | N14: =IF(OR(B14="Sat", B14="Sun"), "", 8)
A15: =A14+1 -> 46243 | B15: =text(A15,"ddd") -> Sun | G15: =IF(COUNTIF(Holidays!$A$2:$A$12,$A15)>0, 8,"") | M15: =IF(OR(B15="Sat", B15="Sun"), "", sum(C15:J15)) | N15: =IF(OR(B15="Sat", B15="Sun"), "", 8)
A16: =A15+1 -> 46244 | B16: =text(A16,"ddd") -> Mon | C16: 9 | D16: 0.5 | G16: =IF(COUNTIF(Holidays!$A$2:$A$12,$A16)>0, 8,"") | M16: =IF(OR(B16="Sat", B16="Sun"), "", sum(C16:J16)) -> 9.5 | N16: =IF(OR(B16="Sat", B16="Sun"), "", 8) -> 8 | P16: 0.34375 | Q16: 0.73958333 | R16: =(Q16-P16)*24 -> 9.5
A17: =A16+1 -> 46245 | B17: =text(A17,"ddd") -> Tue | C17: 8 | D17: 0.25 | G17: =IF(COUNTIF(Holidays!$A$2:$A$12,$A17)>0, 8,"") | M17: =IF(OR(B17="Sat", B17="Sun"), "", sum(C17:J17)) -> 8.25 | N17: =IF(OR(B17="Sat", B17="Sun"), "", 8) -> 8 | P17: 0.39583333 | Q17: 0.73958333 | R17: =(Q17-P17)*24 -> 8.25
A18: =A17+1 -> 46246 | B18: =text(A18,"ddd") -> Wed | C18: 8.25 | G18: =IF(COUNTIF(Holidays!$A$2:$A$12,$A18)>0, 8,"") | M18: =IF(OR(B18="Sat", B18="Sun"), "", sum(C18:J18)) -> 8.25 | N18: =IF(OR(B18="Sat", B18="Sun"), "", 8) -> 8 | P18: 0.34375 | Q18: 0.69791667 | R18: =(Q18-P18)*24 -> 8.5
A19: =A18+1 -> 46247 | B19: =text(A19,"ddd") -> Thu | C19: 7.75 | G19: =IF(COUNTIF(Holidays!$A$2:$A$12,$A19)>0, 8,"") | M19: =IF(OR(B19="Sat", B19="Sun"), "", sum(C19:J19)) -> 7.75 | N19: =IF(OR(B19="Sat", B19="Sun"), "", 8) -> 8 | P19: 0.375 | Q19: 0.69791667 | R19: =(Q19-P19)*24 -> 7.75
A20: =A19+1 -> 46248 | B20: =text(A20,"ddd") -> Fri | C20: 7 | D20: 0.25 | G20: =IF(COUNTIF(Holidays!$A$2:$A$12,$A20)>0, 8,"") | M20: =IF(OR(B20="Sat", B20="Sun"), "", sum(C20:J20)) -> 7.25 | N20: =IF(OR(B20="Sat", B20="Sun"), "", 8) -> 8 | P20: 0.3125 | Q20: 0.72916667 | R20: =(Q20-P20)*24 -> 10 | S20: =R20-3 -> 7
A21: =A20+1 -> 46249 | B21: =text(A21,"ddd") -> Sat | G21: =IF(COUNTIF(Holidays!$A$2:$A$12,$A21)>0, 8,"") | M21: =IF(OR(B21="Sat", B21="Sun"), "", sum(C21:J21)) | N21: =IF(OR(B21="Sat", B21="Sun"), "", 8)
A22: Totals | C22: =sum(C7:C21) -> 80 | D22: =sum(D7:D21) -> 5.75 | E22: =sum(E7:E21) -> 0 | F22: =sum(F7:F21) -> 0 | G22: =sum(G7:G21) -> 0 | H22: =sum(H7:H21) -> 0 | I22: =sum(I7:I21) -> 0 | J22: =sum(J7:J21) -> 0 | ... N22: =sum(N7:N21) -> 80 | R22: =sum(R7:R21) -> 88.75
A25: Pay Period 2 | B25: Weekday | C25: {=transpose('Time Types'!A2:A11)} -> Regular | D25: Bank-Save | E25: Bank-Use | F25: PTO | G25: Holiday | H25: Government | I25: F.Holiday | J25: Training | K25: Overhead | L25: Other | M25: Total | N25: Estimated
A26: =A21+1 -> 46250 | B26: =text(A26,"ddd") -> Sun | G26: =IF(COUNTIF(Holidays!$A$2:$A$12,$A26)>0, 8,"") | M26: =IF(OR(B26="Sat", B26="Sun"), "", sum(C26:J26)) | N26: =IF(OR(B26="Sat", B26="Sun"), "", 8)
A27: =A26+1 -> 46251 | B27: =text(A27,"ddd") -> Mon | C27: 9.5 | G27: =IF(COUNTIF(Holidays!$A$2:$A$12,$A27)>0, 8,"") | M27: =IF(OR(B27="Sat", B27="Sun"), "", sum(C27:J27)) -> 9.5 | N27: =IF(OR(B27="Sat", B27="Sun"), "", 8) -> 8 | P27: 0.34027778 | Q27: 0.73611111 | R27: =(Q27-P27)*24 -> 9.5 | S27: 9.5
A28: =A27+1 -> 46252 | B28: =text(A28,"ddd") -> Tue | C28: 9.25 | G28: =IF(COUNTIF(Holidays!$A$2:$A$12,$A28)>0, 8,"") | M28: =IF(OR(B28="Sat", B28="Sun"), "", sum(C28:J28)) -> 9.25 | N28: =IF(OR(B28="Sat", B28="Sun"), "", 8) -> 8 | P28: 0.35416667 | Q28: 0.73958333 | R28: =(Q28-P28)*24 -> 9.25 | S28: 9.25
A29: =A28+1 -> 46253 | B29: =text(A29,"ddd") -> Wed | C29: 8.25 | G29: =IF(COUNTIF(Holidays!$A$2:$A$12,$A29)>0, 8,"") | M29: =IF(OR(B29="Sat", B29="Sun"), "", sum(C29:J29)) -> 8.25 | N29: =IF(OR(B29="Sat", B29="Sun"), "", 8) -> 8 | P29: 0.33333333 | Q29: 0.69791667 | R29: =(Q29-P29)*24 -> 8.75 | S29: =R29-0.5 -> 8.25
A30: =A29+1 -> 46254 | B30: =text(A30,"ddd") -> Thu | C30: 7.75 | G30: =IF(COUNTIF(Holidays!$A$2:$A$12,$A30)>0, 8,"") | M30: =IF(OR(B30="Sat", B30="Sun"), "", sum(C30:J30)) -> 7.75 | N30: =IF(OR(B30="Sat", B30="Sun"), "", 8) -> 8 | P30: 0.29166667 | Q30: 0.64583333 | R30: =(Q30-P30)*24 -> 8.5 | S30: 7.75
A31: =A30+1 -> 46255 | B31: =text(A31,"ddd") -> Fri | E31: 8 | G31: =IF(COUNTIF(Holidays!$A$2:$A$12,$A31)>0, 8,"") | M31: =IF(OR(B31="Sat", B31="Sun"), "", sum(C31:J31)) -> 8 | N31: =IF(OR(B31="Sat", B31="Sun"), "", 8) -> 8 | P31: 0.32291667 | Q31: 0.64583333 | R31: =(Q31-P31)*24 -> 7.75 | S31: 8
A32: =A31+1 -> 46256 | B32: =text(A32,"ddd") -> Sat | G32: =IF(COUNTIF(Holidays!$A$2:$A$12,$A32)>0, 8,"") | M32: =IF(OR(B32="Sat", B32="Sun"), "", sum(C32:J32)) | N32: =IF(OR(B32="Sat", B32="Sun"), "", 8)
A33: =A32+1 -> 46257 | B33: =text(A33,"ddd") -> Sun | G33: =IF(COUNTIF(Holidays!$A$2:$A$12,$A33)>0, 8,"") | M33: =IF(OR(B33="Sat", B33="Sun"), "", sum(C33:J33)) | N33: =IF(OR(B33="Sat", B33="Sun"), "", 8)
A34: =A33+1 -> 46258 | B34: =text(A34,"ddd") -> Mon | E34: 8 | G34: =IF(COUNTIF(Holidays!$A$2:$A$12,$A34)>0, 8,"") | M34: =IF(OR(B34="Sat", B34="Sun"), "", sum(C34:J34)) -> 8 | N34: =IF(OR(B34="Sat", B34="Sun"), "", 8) -> 8 | P34: 0.33333333 | Q34: 0.66666667 | R34: =(Q34-P34)*24 -> 8 | S34: 8
A35: =A34+1 -> 46259 | B35: =text(A35,"ddd") -> Tue | F35: 5 | G35: =IF(COUNTIF(Holidays!$A$2:$A$12,$A35)>0, 8,"") | M35: =IF(OR(B35="Sat", B35="Sun"), "", sum(C35:J35)) -> 5 | N35: =IF(OR(B35="Sat", B35="Sun"), "", 8) -> 8 | P35: 0.33333333 | Q35: 0.66666667 | R35: =(Q35-P35)*24 -> 8 | S35: 4
A36: =A35+1 -> 46260 | B36: =text(A36,"ddd") -> Wed | F36: 8 | G36: =IF(COUNTIF(Holidays!$A$2:$A$12,$A36)>0, 8,"") | M36: =IF(OR(B36="Sat", B36="Sun"), "", sum(C36:J36)) -> 8 | N36: =IF(OR(B36="Sat", B36="Sun"), "", 8) -> 8 | P36: 0.33333333 | Q36: 0.66666667 | R36: =(Q36-P36)*24 -> 8 | S36: 8
A37: =A36+1 -> 46261 | B37: =text(A37,"ddd") -> Thu | F37: 8 | G37: =IF(COUNTIF(Holidays!$A$2:$A$12,$A37)>0, 8,"") | M37: =IF(OR(B37="Sat", B37="Sun"), "", sum(C37:J37)) -> 8 | N37: =IF(OR(B37="Sat", B37="Sun"), "", 8) -> 8 | P37: 0.33333333 | Q37: 0.66666667 | R37: =(Q37-P37)*24 -> 8 | S37: 8
A38: =A37+1 -> 46262 | B38: =text(A38,"ddd") -> Fri | C38: 8.25 | G38: =IF(COUNTIF(Holidays!$A$2:$A$12,$A38)>0, 8,"") | M38: =IF(OR(B38="Sat", B38="Sun"), "", sum(C38:J38)) -> 8.25 | N38: =IF(OR(B38="Sat", B38="Sun"), "", 8) -> 8 | P38: 0.34722222 | Q38: 0.68055556 | R38: =(Q38-P38)*24 -> 8 | S38: 8.25
A39: =A38+1 -> 46263 | B39: =text(A39,"ddd") -> Sat | G39: =IF(COUNTIF(Holidays!$A$2:$A$12,$A39)>0, 8,"") | M39: =IF(OR(B39="Sat", B39="Sun"), "", sum(C39:J39)) | N39: =IF(OR(B39="Sat", B39="Sun"), "", 8)
A40: =A39+1 -> 46264 | B40: =text(A40,"ddd") -> Sun | G40: =IF(COUNTIF(Holidays!$A$2:$A$12,$A40)>0, 8,"") | M40: =IF(OR(B40="Sat", B40="Sun"), "", sum(C40:J40)) | N40: =IF(OR(B40="Sat", B40="Sun"), "", 8)
A41: =A40+1 -> 46265 | B41: =text(A41,"ddd") -> Mon | C41: 8 | G41: =IF(COUNTIF(Holidays!$A$2:$A$12,$A41)>0, 8,"") | M41: =IF(OR(B41="Sat", B41="Sun"), "", sum(C41:J41)) -> 8 | N41: =IF(OR(B41="Sat", B41="Sun"), "", 8) -> 8 | P41: 0.35416667 | Q41: 0.6875 | R41: =(Q41-P41)*24 -> 8 | S41: 8
A42: Totals | C42: =sum(C26:C41) -> 51 | D42: =sum(D26:D41) -> 0 | E42: =sum(E26:E41) -> 16 | F42: =sum(F26:F41) -> 21 | G42: =sum(G26:G41) -> 0 | H42: =sum(H26:H41) -> 0 | I42: =sum(I26:I41) -> 0 | J42: =sum(J26:J41) -> 0 | ... N42: =sum(N26:N41) -> 88 | R42: =sum(R25:R41) -> 91.75 | S42: =sum(S27:S41) -> 87

Sheet Sep 26
A1: September | B1: PTO Totals | C1: Bank Totals | D1: F.Holiday Total | E1: Training Total
A2: Start of Month | B2: {=INDIRECT(TEXT(EDATE(DATE(2026, MATCH($A$1, {"January","February","March","April","May","June","July","August","September","October","November","December"}, 0), 1), -1), "mmm") & " 26!B4")} -> 72.5 | C2: {=INDIRECT(TEXT(EDATE(DATE(2026, MATCH($A$1, {"January","February","March","April","May","June","July","August","September","October","November","December"}, 0), 1), -1), "mmm") & " 26!C4")} -> 1.25 | D2: {=INDIRECT(TEXT(EDATE(DATE(2026, MATCH($A$1, {"January","February","March","April","May","June","July","August","September","October","November","December"}, 0), 1), -1), "mmm") & " 26!D4")} -> 8 | E2: {=INDIRECT(TEXT(EDATE(DATE(2026, MATCH($A$1, {"January","February","March","April","May","June","July","August","September","October","November","December"}, 0), 1), -1), "mmm") & " 26!E4")} -> 40 | G2: Earning Rate | H2: ='START HERE'!B6 -> 5
A3: End of Period 1 | B3: =B2+H2-F22 -> 77.5 | C3: =C2+D22-E22 -> 7 | D3: =D2-I22 -> 8 | E3: =E2-J22 -> 40
A4: End of Period 2 | B4: =B3+H2-F42 -> 82.5 | C4: =C3+D42-E42 -> 13.5 | D4: =D3-I42 -> 8 | E4: =E3-J42 -> 40
P5: IN | Q5: OUT | R5: Duration
A6: Pay Period 1 | B6: Weekday | C6: {=TRANSPOSE('Time Types'!A2:A11)} -> Regular | D6: Bank-Save | E6: Bank-Use | F6: PTO | G6: Holiday | H6: Government | I6: F.Holiday | J6: Training | K6: Overhead | L6: Other | M6: Total | N6: Estimated
A7: =DATE(2026, MONTH(DATEVALUE($A$1 & " 1")), 1) -> 46266 | B7: =text(A7,"ddd") -> Tue | C7: 8 | D7: 1.5 | G7: =IF(COUNTIF(Holidays!$A$2:$A$12,$A7)>0, 8,"") | M7: =IF(OR(B7="Sat", B7="Sun"), "", sum(C7:J7)) -> 9.5 | N7: =IF(OR(B7="Sat", B7="Sun"), "", 8) -> 8 | P7: 0.34375 | Q7: 0.73958333 | R7: =(Q7-P7)*24 -> 9.5
A8: =A7+1 -> 46267 | B8: =text(A8,"ddd") -> Wed | C8: 8 | D8: 1.5 | G8: =IF(COUNTIF(Holidays!$A$2:$A$12,$A8)>0, 8,"") | M8: =IF(OR(B8="Sat", B8="Sun"), "", sum(C8:J8)) -> 9.5 | N8: =IF(OR(B8="Sat", B8="Sun"), "", 8) -> 8 | P8: 0.30208333 | Q8: 0.69791667 | R8: =(Q8-P8)*24 -> 9.5
A9: =A8+1 -> 46268 | B9: =text(A9,"ddd") -> Thu | C9: 8 | D9: 1.25 | G9: =IF(COUNTIF(Holidays!$A$2:$A$12,$A9)>0, 8,"") | M9: =IF(OR(B9="Sat", B9="Sun"), "", sum(C9:J9)) -> 9.25 | N9: =IF(OR(B9="Sat", B9="Sun"), "", 8) -> 8 | P9: 0.35416667 | Q9: 0.73958333 | R9: =(Q9-P9)*24 -> 9.25
A10: =A9+1 -> 46269 | B10: =text(A10,"ddd") -> Fri | C10: 8 | D10: 0.5 | G10: =IF(COUNTIF(Holidays!$A$2:$A$12,$A10)>0, 8,"") | M10: =IF(OR(B10="Sat", B10="Sun"), "", sum(C10:J10)) -> 8.5 | N10: =IF(OR(B10="Sat", B10="Sun"), "", 8) -> 8 | P10: 0.34375 | Q10: 0.69791667 | R10: =(Q10-P10)*24 -> 8.5
A11: =A10+1 -> 46270 | B11: =text(A11,"ddd") -> Sat | G11: =IF(COUNTIF(Holidays!$A$2:$A$12,$A11)>0, 8,"") | M11: =IF(OR(B11="Sat", B11="Sun"), "", sum(C11:J11)) | N11: =IF(OR(B11="Sat", B11="Sun"), "", 8)
A12: =A11+1 -> 46271 | B12: =text(A12,"ddd") -> Sun | G12: =IF(COUNTIF(Holidays!$A$2:$A$12,$A12)>0, 8,"") | M12: =IF(OR(B12="Sat", B12="Sun"), "", sum(C12:J12)) | N12: =IF(OR(B12="Sat", B12="Sun"), "", 8)
A13: =A12+1 -> 46272 | B13: =text(A13,"ddd") -> Mon | G13: =IF(COUNTIF(Holidays!$A$2:$A$12,$A13)>0, 8,"") -> 8 | M13: =IF(OR(B13="Sat", B13="Sun"), "", sum(C13:J13)) -> 8 | N13: =IF(OR(B13="Sat", B13="Sun"), "", 8) -> 8 | P13: 0.33333333 | Q13: 0.66666667 | R13: =(Q13-P13)*24 -> 8
A14: =A13+1 -> 46273 | B14: =text(A14,"ddd") -> Tue | C14: 8 | D14: 1 | G14: =IF(COUNTIF(Holidays!$A$2:$A$12,$A14)>0, 8,"") | M14: =IF(OR(B14="Sat", B14="Sun"), "", sum(C14:J14)) -> 9 | N14: =IF(OR(B14="Sat", B14="Sun"), "", 8) -> 8 | P14: 0.36458333 | Q14: 0.73958333 | R14: =(Q14-P14)*24 -> 9
A15: =A14+1 -> 46274 | B15: =text(A15,"ddd") -> Wed | C15: 8.5 | G15: =IF(COUNTIF(Holidays!$A$2:$A$12,$A15)>0, 8,"") | M15: =IF(OR(B15="Sat", B15="Sun"), "", sum(C15:J15)) -> 8.5 | N15: =IF(OR(B15="Sat", B15="Sun"), "", 8) -> 8 | P15: 0.36458333 | Q15: 0.71875 | R15: =(Q15-P15)*24 -> 8.5
A16: =A15+1 -> 46275 | B16: =text(A16,"ddd") -> Thu | C16: 8.5 | G16: =IF(COUNTIF(Holidays!$A$2:$A$12,$A16)>0, 8,"") | M16: =IF(OR(B16="Sat", B16="Sun"), "", sum(C16:J16)) -> 8.5 | N16: =IF(OR(B16="Sat", B16="Sun"), "", 8) -> 8 | P16: 0.375 | Q16: 0.71875 | R16: =(Q16-P16)*24 -> 8.25
A17: =A16+1 -> 46276 | B17: =text(A17,"ddd") -> Fri | C17: 5 | G17: =IF(COUNTIF(Holidays!$A$2:$A$12,$A17)>0, 8,"") | M17: 5 | N17: =IF(OR(B17="Sat", B17="Sun"), "", 8) -> 8 | P17: 0.39583333 | Q17: 0.60416667 | R17: =(Q17-P17)*24 -> 5
A18: =A17+1 -> 46277 | B18: =text(A18,"ddd") -> Sat | M18: =IF(OR(B18="Sat", B18="Sun"), "", sum(C18:J18)) | N18: =IF(OR(B18="Sat", B18="Sun"), "", 8)
A19: =A18+1 -> 46278 | B19: =text(A19,"ddd") -> Sun | G19: =IF(COUNTIF(Holidays!$A$2:$A$12,$A19)>0, 8,"") | M19: =IF(OR(B19="Sat", B19="Sun"), "", sum(C19:J19)) | N19: =IF(OR(B19="Sat", B19="Sun"), "", 8)
A20: =A19+1 -> 46279 | B20: =text(A20,"ddd") -> Mon | C20: 9 | G20: =IF(COUNTIF(Holidays!$A$2:$A$12,$A20)>0, 8,"") | M20: =IF(OR(B20="Sat", B20="Sun"), "", sum(C20:J20)) -> 9 | N20: =IF(OR(B20="Sat", B20="Sun"), "", 8) -> 8 | P20: 0.33333333 | Q20: 0.66666667 | R20: =(Q20-P20)*24 -> 8
A21: =A20+1 -> 46280 | B21: =text(A21,"ddd") -> Tue | C21: 9 | G21: =IF(COUNTIF(Holidays!$A$2:$A$12,$A21)>0, 8,"") | M21: =IF(OR(B21="Sat", B21="Sun"), "", sum(C21:J21)) -> 9 | N21: =IF(OR(B21="Sat", B21="Sun"), "", 8) -> 8 | P21: 0.33333333 | Q21: 0.66666667 | R21: =(Q21-P21)*24 -> 8
